<?xml version='1.0' encoding='utf-8'?>
<robot name="RPR_robot">

    <link name="link0">
      <inertial>
        <origin xyz="0 0 0" rpy="0 0 0" />
        <mass value="0.001" />
        <inertia ixx="0.2" iyy="0.2" izz="0.2" ixy="0" ixz="0" iyz="0" />
      </inertial>
      <visual>
        <origin xyz="0 0 0" rpy="0 0 0" />
        <geometry>
          <mesh filename="./meshes/RPR_base.obj"/>
        </geometry>
      </visual>
    </link>
    <link name="link1">
      <inertial>
        <origin xyz="0.1 0 0.15421" rpy="0 0 0" />
        <mass value="0.1" />
        <inertia ixx="0.1" iyy="0.1" izz="0.1" ixy="0" ixz="0" iyz="0" />
      </inertial>
      <visual>
        <origin xyz="0 0 0" rpy="0 0 0" />
        <geometry>
          <mesh filename="./meshes/RPR_link1.obj"/>
        </geometry>
      </visual>
    </link>
    <link name="link2">
      <inertial>
        <origin xyz="0.1 0 0.19357" rpy="0 0 0" />
        <mass value="0.1" />
        <inertia ixx="0.1" iyy="0.1" izz="0.1" ixy="0" ixz="0" iyz="0" />
      </inertial>
      <visual>
        <origin xyz="0 0 0" rpy="0 0 0" />
        <geometry>
          <mesh filename="./meshes/RPR_link2.obj"/>
        </geometry>
      </visual>
    </link>
    <link name="link3">
      <inertial>
        <origin xyz="0.15 0 0" rpy="0 0 0" />
        <mass value="0.1" />
        <inertia ixx="0.1" iyy="0.1" izz="0.1" ixy="0" ixz="0" iyz="0" />
      </inertial>
      <visual>
        <origin xyz="-0.1 0 -0.24438" rpy="0 0 0" />
        <geometry>
          <mesh filename="./meshes/RPR_link3.obj"/>
        </geometry>
      </visual>
    </link>
    
    <joint name="joint1" type="revolute">
      <origin xyz="0 0 0" rpy="0 0 0" />
      <parent link="link0"/>
      <child link="link1"/>
      <axis xyz="0 0 1"/>
      <limit effort="21.3" lower="-100" upper="100" velocity="21.3"/>
    </joint>
    <joint name="joint2" type="prismatic">
      <origin xyz="-0.1 0 0" rpy="0 0 0" />
      <parent link="link1"/>
      <child link="link2"/>
      <axis xyz="1 0 0"/>
      <limit effort="21.3" lower="-100" upper="100" velocity="21.3"/>
    </joint>
    <joint name="joint3" type="revolute">
      <origin xyz="0.1 0 0.24438" rpy="0 0 0" />
      <parent link="link2"/>
      <child link="link3"/>
      <axis xyz="0 1 0"/>
      <limit effort="21.3" lower="-100" upper="100" velocity="21.3"/>
    </joint>
</robot>
</xml>